Workbook

Sheet GA
A1: mainTest | B1: experiment | C1: expParameter | D1: experimentId | E1: runId | F1: objBest | G1: leadBest | H1: toolBest | I1: PalletBest | J1: avgDuration
A2: Sensitivity | B2: AM | C2: 0 | D2: 1 | E2: 1 | F2: 218742.02 | G2: 999999 | H2: 999999 | I2: 9999999 | J2: 26.665038
A3: Sensitivity | B3: AM | C3: 0 | D3: 1 | E3: 2 | F3: 221112.02 | G3: 999999 | H3: 999999 | I3: 9999999 | J3: 27.359181
A4: Sensitivity | B4: AM | C4: 0 | D4: 1 | E4: 3 | F4: 223446.01 | G4: 999999 | H4: 999999 | I4: 9999999 | J4: 26.933877
A5: Sensitivity | B5: AM | C5: 0 | D5: 1 | E5: 4 | F5: 220088.03 | G5: 999999 | H5: 999999 | I5: 9999999 | J5: 26.90331
A6: Sensitivity | B6: AM | C6: 0 | D6: 1 | E6: 5 | F6: 218946.01 | G6: 999999 | H6: 999999 | I6: 9999999 | J6: 26.949176
A7: Sensitivity | B7: AM | C7: 0 | D7: 1 | E7: 6 | F7: 222250.55 | G7: 999999 | H7: 999999 | I7: 9999999 | J7: 26.750196
A8: Sensitivity | B8: AM | C8: 0 | D8: 1 | E8: 7 | F8: 219213.65 | G8: 999999 | H8: 999999 | I8: 9999999 | J8: 27.446305
A9: Sensitivity | B9: AM | C9: 0 | D9: 1 | E9: 8 | F9: 221613.65 | G9: 999999 | H9: 999999 | I9: 9999999 | J9: 26.872826
A10: Sensitivity | B10: AM | C10: 0 | D10: 1 | E10: 9 | F10: 220817.64 | G10: 999999 | H10: 999999 | I10: 9999999 | J10: 27.588162
A11: Sensitivity | B11: AM | C11: 0 | D11: 1 | E11: 10 | F11: 219222.02 | G11: 999999 | H11: 999999 | I11: 9999999 | J11: 27.11607
A12: Sensitivity | B12: AM | C12: 0.25 | D12: 1 | F12: 225622.02 | G12: 73252.02 | H12: 74970 | I12: 77400 | J12: 19.94231
A13: Sensitivity | B13: AM | C13: 0.25 | D13: 1 | F13: 223407.01 | G13: 73507.015 | H13: 75100 | I13: 74800 | J13: 20.833778
A14: Sensitivity | B14: AM | C14: 0.25 | D14: 1 | F14: 219912.02 | G14: 73252.02 | H14: 73860 | I14: 72800 | J14: 21.015319
A15: Sensitivity | B15: AM | C15: 0.25 | D15: 1 | F15: 223923.65 | G15: 74063.647 | H15: 74460 | I15: 75400 | J15: 20.873025
A16: Sensitivity | B16: AM | C16: 0.25 | D16: 1 | F16: 222908.03 | G16: 73878.029 | H16: 74030 | I16: 75000 | J16: 20.586324
A17: Sensitivity | B17: AM | C17: 0.25 | D17: 1 | F17: 221238.81 | G17: 73198.805 | H17: 74640 | I17: 73400 | J17: 20.850396
A18: Sensitivity | B18: AM | C18: 0.25 | D18: 1 | F18: 231190 | G18: 74880 | H18: 75310 | I18: 81000 | J18: 21.15415
A19: Sensitivity | B19: AM | C19: 0.25 | D19: 1 | F19: 222356.01 | G19: 72626.01 | H19: 75530 | I19: 74200 | J19: 20.790711
A20: Sensitivity | B20: AM | C20: 0.25 | D20: 1 | F20: 225438.03 | G20: 73878.029 | H20: 74360 | I20: 77200 | J20: 20.952968
A21: Sensitivity | B21: AM | C21: 0.25 | D21: 1 | F21: 223185.53 | G21: 74005.527 | H21: 73780 | I21: 75400 | J21: 20.635659
A22: Sensitivity | B22: AM | C22: 0.5 | D22: 1 | F22: 227221.63 | G22: 73291.628 | H22: 74330 | I22: 79600 | J22: 20.946332
A23: Sensitivity | B23: AM | C23: 0.5 | D23: 1 | F23: 225486.01 | G23: 72626.01 | H23: 74860 | I23: 78000 | J23: 21.508452
... A51: Sensitivity | B51: AM | C51: 1 | D51: 1 | F51: 228546.01 | G51: 72626.01 | H51: 73720 | I51: 82200 | J51: 21.177569
A52: Sensitivity | B52: S | C52: 8 | D52: 1 | E52: 1 | F52: 302562.34 | G52: 147592.34 | H52: 74770 | I52: 80200 | J52: 26.197988
A53: Sensitivity | B53: S | C53: 8 | D53: 1 | E53: 2 | F53: 300780.22 | G53: 144770.22 | H53: 74610 | I53: 81400 | J53: 26.528674
A54: Sensitivity | B54: S | C54: 8 | D54: 1 | E54: 3 | F54: 303497.5 | G54: 149887.5 | H54: 75010 | I54: 78600 | J54: 26.855344
A55: Sensitivity | B55: S | C55: 8 | D55: 1 | E55: 4 | F55: 301811.63 | G55: 147691.63 | H55: 74320 | I55: 79800 | J55: 26.540096
A56: Sensitivity | B56: S | C56: 8 | D56: 1 | E56: 5 | F56: 304376.01 | G56: 147506.01 | H56: 75670 | I56: 81200 | J56: 26.436583
A57: Sensitivity | B57: S | C57: 8 | D57: 1 | E57: 6 | F57: 301135.62 | G57: 144665.62 | H57: 75470 | I57: 81000 | J57: 26.070682
A58: Sensitivity | B58: S | C58: 8 | D58: 1 | E58: 7 | F58: 306682.02 | G58: 150532.02 | H58: 74350 | I58: 81800 | J58: 26.766092
A59: Sensitivity | B59: S | C59: 8 | D59: 1 | E59: 8 | F59: 301350 | G59: 149760 | H59: 74790 | I59: 76800 | J59: 26.1724
A60: Sensitivity | B60: S | C60: 8 | D60: 1 | E60: 9 | F60: 305370 | G60: 149760 | H60: 75010 | I60: 80600 | J60: 26.106367
A61: Sensitivity | B61: S | C61: 8 | D61: 1 | E61: 10 | F61: 301734.99 | G61: 147614.99 | H61: 74920 | I61: 79200 | J61: 26.126222
A62: Sensitivity | B62: S | C62: 12 | D62: 1 | E62: 1 | F62: 257002.02 | G62: 104932.02 | H62: 74470 | I62: 77600 | J62: 26.350743
A63: Sensitivity | B63: S | C63: 12 | D63: 1 | E63: 2 | F63: 256017.64 | G63: 105117.64 | H63: 75100 | I63: 75800 | J63: 26.769516
... A111: Sensitivity | B111: S | C111: 24 | D111: 1 | E111: 10 | F111: 200785.11 | G111: 60255.114 | H111: 74530 | I111: 66000 | J111: 28.360621
A112: Sensitivity | B112: TH | C112: 0.75 | D112: 1 | F112: 218409.03 | G112: 74039.034 | H112: 73370 | I112: 71000 | J112: 24.824644
A113: Sensitivity | B113: TH | C113: 0.75 | D113: 1 | F113: 222154.04 | G113: 72824.039 | H113: 72530 | I113: 76800 | J113: 24.245185
A114: Sensitivity | B114: TH | C114: 0.75 | D114: 1 | F114: 220317.64 | G114: 73917.638 | H114: 74400 | I114: 72000 | J114: 24.494461
...

Sheet PH
A1: mainTest | B1: experiment | C1: parameter | D1: run | E1: ObjBest
A2: Sensitivity | B2: AM | C2: 0 | D2: 1 | E2: 277664.04
A3: Sensitivity | B3: AM | C3: 0 | D3: 2 | E3: 277664.04
A4: Sensitivity | B4: AM | C4: 0 | D4: 3 | E4: 277664.04
A5: Sensitivity | B5: AM | C5: 0 | D5: 4 | E5: 277664.04
A6: Sensitivity | B6: AM | C6: 0 | D6: 5 | E6: 277664.04
A7: Sensitivity | B7: AM | C7: 0 | D7: 6 | E7: 277664.04
A8: Sensitivity | B8: AM | C8: 0 | D8: 7 | E8: 277664.04
A9: Sensitivity | B9: AM | C9: 0 | D9: 8 | E9: 277664.04
A10: Sensitivity | B10: AM | C10: 0 | D10: 9 | E10: 277664.04
A11: Sensitivity | B11: AM | C11: 0 | D11: 10 | E11: 277664.04
A12: Sensitivity | B12: AM | C12: 0.25 | D12: 1 | E12: 276985.39
A13: Sensitivity | B13: AM | C13: 0.25 | D13: 2 | E13: 276985.39
... A171: Sensitivity | B171: TH | C171: 2 | D171: 10 | E171: 292872.66

Sheet Comparison
A1: experiment | B1: expParameter | C1: PH | D1: GA | F1: AM:0 | G1: GA | H1: PH | J1: AM:0.25 | K1: GA | L1: PH
A2: AM | B2: 0 | C2: =AVERAGEIFS(PH!E:E,PH!B:B,Comparison!A2,PH!C:C,Comparison!B2) -> 277664.04 | D2: =AVERAGEIFS(GA!F:F,GA!B:B,Comparison!A2,GA!C:C,Comparison!B2) -> 220545.16 | F2: Gemiddelde | G2: 277664.04 | H2: 220545.16 | J2: Gemiddelde | K2: 276985.39 | L2: 223918.11
A3: AM | B3: 0.25 | C3: =AVERAGEIFS(PH!E:E,PH!B:B,Comparison!A3,PH!C:C,Comparison!B3) -> 276985.39 | D3: =AVERAGEIFS(GA!F:F,GA!B:B,Comparison!A3,GA!C:C,Comparison!B3) -> 223918.11 | F3: Variantie | G3: 3.7645909e-21 | H3: 2489080.4 | J3: Variantie | K3: 0 | L3: 9508847.5
A4: AM | B4: 0.5 | C4: =AVERAGEIFS(PH!E:E,PH!B:B,Comparison!A4,PH!C:C,Comparison!B4) -> 281376.01 | D4: =AVERAGEIFS(GA!F:F,GA!B:B,Comparison!A4,GA!C:C,Comparison!B4) -> 224709.13 | F4: Waarnemingen | G4: 10 | H4: 10 | J4: Waarnemingen | K4: 10 | L4: 10
A5: AM | B5: 0.75 | C5: =AVERAGEIFS(PH!E:E,PH!B:B,Comparison!A5,PH!C:C,Comparison!B5) -> 301375.63 | D5: =AVERAGEIFS(GA!F:F,GA!B:B,Comparison!A5,GA!C:C,Comparison!B5) -> 238909.16 | F5: Pearson-correlatie | G5: -3.8890133e-15 | J5: Pearson-correlatie | K5: #DIV/0!
A6: AM | B6: 1 | C6: =AVERAGEIFS(PH!E:E,PH!B:B,Comparison!A6,PH!C:C,Comparison!B6) -> 295078.03 | D6: =AVERAGEIFS(GA!F:F,GA!B:B,Comparison!A6,GA!C:C,Comparison!B6) -> 226071.51 | F6: Schatting van verschil tussen gemiddelden | G6: 0 | J6: Schatting van verschil tussen gemiddelden | K6: 0
A7: S | B7: 8 | C7: =AVERAGEIFS(PH!E:E,PH!B:B,Comparison!A7,PH!C:C,Comparison!B7) -> 394770 | D7: =AVERAGEIFS(GA!F:F,GA!B:B,Comparison!A7,GA!C:C,Comparison!B7) -> 302930.03 | F7: Vrijheidsgraden | G7: 9 | J7: Vrijheidsgraden | K7: 9
A8: S | B8: 12 | C8: =AVERAGEIFS(PH!E:E,PH!B:B,Comparison!A8,PH!C:C,Comparison!B8) -> 325690 | D8: =AVERAGEIFS(GA!F:F,GA!B:B,Comparison!A8,GA!C:C,Comparison!B8) -> 255879.71 | F8: T- statistische gegevens | G8: 114.48807 | J8: T- statistische gegevens | K8: 54.420546
A9: S | B9: 16 | C9: =AVERAGEIFS(PH!E:E,PH!B:B,Comparison!A9,PH!C:C,Comparison!B9) -> 289174.04 | D9: =AVERAGEIFS(GA!F:F,GA!B:B,Comparison!A9,GA!C:C,Comparison!B9) -> 229237.32 | F9: P(T<=t) eenzijdig | G9: 7.512411e-16 | J9: P(T<=t) eenzijdig | K9: 6.0059782e-13
A10: S | B10: 18 | C10: =AVERAGEIFS(PH!E:E,PH!B:B,Comparison!A10,PH!C:C,Comparison!B10) -> 277664.04 | D10: =AVERAGEIFS(GA!F:F,GA!B:B,Comparison!A10,GA!C:C,Comparison!B10) -> 220545.16 | F10: Kritiek gebied van T-toets: eenzijdig | G10: 1.8331129 | J10: Kritiek gebied van T-toets: eenzijdig | K10: 1.8331129
A11: S | B11: 20 | C11: =AVERAGEIFS(PH!E:E,PH!B:B,Comparison!A11,PH!C:C,Comparison!B11) -> 266568.03 | D11: =AVERAGEIFS(GA!F:F,GA!B:B,Comparison!A11,GA!C:C,Comparison!B11) -> 212966.25 | F11: P(T<=t) tweezijdig | G11: 1.5024822e-15 | J11: P(T<=t) tweezijdig | K11: 1.2011956e-12
A12: S | B12: 24 | C12: =AVERAGEIFS(PH!E:E,PH!B:B,Comparison!A12,PH!C:C,Comparison!B12) -> 256551.66 | D12: =AVERAGEIFS(GA!F:F,GA!B:B,Comparison!A12,GA!C:C,Comparison!B12) -> 204033.69 | F12: Kritiek gebied van T-toets: tweezijdig | G12: 2.2621572 | J12: Kritiek gebied van T-toets: tweezijdig | K12: 2.2621572
A13: TH | B13: 0.75 | C13: =AVERAGEIFS(PH!E:E,PH!B:B,Comparison!A13,PH!C:C,Comparison!B13) -> 272842.02 | D13: =AVERAGEIFS(GA!F:F,GA!B:B,Comparison!A13,GA!C:C,Comparison!B13) -> 219122.42
A14: TH | B14: 1 | C14: =AVERAGEIFS(PH!E:E,PH!B:B,Comparison!A14,PH!C:C,Comparison!B14) -> 272842.02 | D14: =AVERAGEIFS(GA!F:F,GA!B:B,Comparison!A14,GA!C:C,Comparison!B14) -> 217751.72 | F14: AM:0.5 | G14: PH | H14: GA | J14: AM:0.75 | K14: PH | L14: GA
A15: TH | B15: 1.25 | C15: =AVERAGEIFS(PH!E:E,PH!B:B,Comparison!A15,PH!C:C,Comparison!B15) -> 282380 | D15: =AVERAGEIFS(GA!F:F,GA!B:B,Comparison!A15,GA!C:C,Comparison!B15) -> 233701.36 | F15: Mean | G15: 281376.01 | H15: 224709.13 | J15: Mean | K15: 301375.63 | L15: 238909.16
A16: TH | B16: 1.5 | C16: =AVERAGEIFS(PH!E:E,PH!B:B,Comparison!A16,PH!C:C,Comparison!B16) -> 293130 | D16: =AVERAGEIFS(GA!F:F,GA!B:B,Comparison!A16,GA!C:C,Comparison!B16) -> 236575.14 | F16: Variance | G16: 3.7645909e-21 | H16: 4934452.6 | J16: Variance | K16: 3.7645909e-21 | L16: 4987512.3
A17: TH | B17: 1.75 | C17: =AVERAGEIFS(PH!E:E,PH!B:B,Comparison!A17,PH!C:C,Comparison!B17) -> 300243.51 | D17: =AVERAGEIFS(GA!F:F,GA!B:B,Comparison!A17,GA!C:C,Comparison!B17) -> 239532.78 | F17: Observations | G17: 10 | H17: 10 | J17: Observations | K17: 10 | L17: 10
A18: TH | B18: 2 | C18: =AVERAGEIFS(PH!E:E,PH!B:B,Comparison!A18,PH!C:C,Comparison!B18) -> 292872.66 | D18: =AVERAGEIFS(GA!F:F,GA!B:B,Comparison!A18,GA!C:C,Comparison!B18) -> 241153.46 | F18: Pearson Correlation | G18: 0 | J18: Pearson Correlation | K18: -1.2363158e-14
F19: Hypothesized Mean Difference | G19: 0 | J19: Hypothesized Mean Difference | K19: 0
F20: df | G20: 9 | J20: df | K20: 9
F21: t Stat | G21: 80.669578 | J21: t Stat | K21: 88.451454
F22: P(T<=t) one-tail | G22: 1.7498359e-14 | J22: P(T<=t) one-tail | K22: 7.6463363e-15
F23: t Critical one-tail | G23: 1.8331129 | J23: t Critical one-tail | K23: 1.8331129
F24: P(T<=t) two-tail | G24: 3.4996719e-14 | J24: P(T<=t) two-tail | K24: 1.5292673e-14
F25: t Critical two-tail | G25: 2.2621572 | J25: t Critical two-tail | K25: 2.2621572
F27: AM:1 | G27: PH | H27: GA
F28: Mean | G28: 295078.03 | H28: 226071.51
F29: Variance | G29: 3.7645909e-21 | H29: 2629772
F30: Observations | G30: 10 | H30: 10
F31: Pearson Correlation | G31: -2.4593096e-14
F32: Hypothesized Mean Difference | G32: 0
F33: df | G33: 9
F34: t Stat | G34: 134.56468
F35: P(T<=t) one-tail | G35: 1.7562176e-16
F36: t Critical one-tail | G36: 1.8331129
F37: P(T<=t) two-tail | G37: 3.5124353e-16
F38: t Critical two-tail | G38: 2.2621572
F40: S:8 | G40: PH | H40: GA | J40: S:12 | K40: PH | L40: GA
F41: Mean | G41: 394770 | H41: 302930.03 | J41: Mean | K41: 325690 | L41: 255879.71
F42: Variance | G42: 0 | H42: 3955106.4 | J42: Variance | K42: 0 | L42: 5859852.9
...
